vue-router 3.0 版本之前的路由跳转，如果出错会终止后面的代码执行， 或者重复路由会有报错

比如： Avoid redundant navigation to current location

解决办法， 手动添加 catch 方法

```js
const originRouterPush = VueRouter.prototype.push

VueRouter.prototype.push = function (location) {
  return originRouterPush.call(this, location).catch(err => err)
}
```

链式调用 catch 方法。旨在在方法执行时，捕获错误。在 js 机制中，catch 捕获到 Exception 时，代码还会继续向下执行。所以此处的 catch 未作任何操作，代码也会继续向下执行。打印捕获到的 err 如下，和抛给浏览器的错误其实时一致的：

此报错不会影响项目的运行，修改原型对象上的 push 函数中添加了一步操作，就是对抛出的错误进行捕获，但是捕获到之后不做任何操作。不做任何操作也不会对重复跳转的组件有任何的影响，也不会对要跳转的组件进行重新渲染，因为他并不会执行重复跳转的操作。
